Traceback (most recent call last):
  File "main.py", line 13, in <module>
    problem_id = sys.argv[1]
IndexError: list index out of range
